Workbook

Sheet Portada
B8: Backlog Scrum
B9: Product Backlog y Sprint Backlog
B10: Acredittia
B12: Revisión: 1.0
B13: 30/10/2026
B15: Contenido del libro
B16: Instrucciones | D16: Origen de los datos y celdas a completar
B17: Product Backlog | D17: 24 historias de usuario con prioridad MoSCoW
B18: Sprint Backlog | D18: 46 tareas por sprint con responsable y estado
B19: Sprints | D19: Resumen y avance por sprint
B21: Ficha del documento
B22: Fecha | C22: Revisión | D22: Autor | E22: Modificación
B23: 30/10/2026 | C23: 1.0 | D23: Equipo Acredittia | E23: Creación del documento
B26: Escuela de Informática y Telecomunicaciones · Duoc UC

Sheet Instrucciones
A1: Backlog Scrum — Acredittia
A2: Documentación de la metodología: Product Backlog, Sprint Backlog y resumen por sprint.
A4: De dónde sale cada dato
A5: • Historias de usuario: se derivan de los requerimientos RF/RNF del Documento de Requerimientos (IEEE 29148).
A6: • Sprints, fechas y objetivos: del Plan de Proyecto (sección 6, Calendarización).
A7: • Estado (Terminado / Parcial / Pendiente) y n.º de endpoints y casos: revisados en el código de Backend_Acredita.
A9: Qué deben completar o ajustar ustedes (celdas en amarillo)
A10: • Puntos (estimación): valores propuestos según la prioridad (Must 8 · Should 5 · Could 3). Reemplácenlos por los que estimó el equipo.
A11: • Responsable de cada tarea del Sprint Backlog: elijan de la lista quién la hizo.
A13: Ejemplo de fila completa (Sprint Backlog): Sprint 1 · HU-02 · Implementar API de Autenticación · 8 endpoints · Responsable: Diego Santiagos · Terminado

Sheet Product Backlog
A1: ID | B1: Épica | C1: Requisito | D1: Historia de usuario | E1: Criterios de aceptación | F1: Prioridad (MoSCoW) | G1: Puntos (estimación) | H1: Sprint | I1: Estado | J1: Observaciones
A2: HU-01 | B2: EP-01 Infraestructura | C2: RNF-12 | D2: Como equipo de desarrollo quiero un entorno reproducible con Docker y un job de migración del esquema para levantar la plataforma igual en local y en la nube | E2: docker compose levanta db, migrate, api, worker, beat y web; la API verifica la versión de esquema al arrancar | F2: Must | G2: 8 | H2: Sprint 1 | I2: Terminado
A3: HU-02 | B3: EP-02 Auth y cuentas | C3: RF-01 | D3: Como empresa contratista quiero registrarme con mi RUT para solicitar acceso a la plataforma | E3: RUT validado; email y RUT únicos; la cuenta queda pendiente de aprobación | F3: Must | G3: 8 | H3: Sprint 1 | I3: Terminado
A4: HU-03 | B4: EP-02 Auth y cuentas | C4: RF-02 | D4: Como administrador quiero aprobar o rechazar solicitudes de empresas para controlar quién opera en la plataforma | E4: Solo admin aprueba o rechaza; una cuenta pendiente no puede iniciar sesión | F4: Must | G4: 8 | H4: Sprint 1 | I4: Terminado
A5: HU-04 | B5: EP-02 Auth y cuentas | C5: RF-03 / RNF-03 | D5: Como usuario quiero iniciar sesión de forma segura y mantener mi sesión para trabajar sin reingresar mis datos | E5: JWT con refresh token revocable; contraseñas con Argon2; el reset revoca todas las sesiones | F5: Must | G5: 8 | H5: Sprint 1 | I5: Terminado
A6: HU-05 | B6: EP-02 Auth y cuentas | C6: RF-04 | D6: Como empresa quiero invitar usuarios internos y administradores de contrato para delegar la gestión | E6: Roles company y contract_admin; un contract_admin solo ve su contrato | F6: Should | G6: 5 | H6: Sprint 1 | I6: Parcial | J6: Endpoints listos; falta enviar el correo de invitación (SMTP)
A7: HU-06 | B7: EP-03 Catálogos maestros | C7: RF-05 | D7: Como administrador quiero mantener el catálogo de faenas, plataformas y plantillas de requisitos para estandarizar las acreditaciones | E7: CRUD de faenas, cargos, plataformas y plantillas maestras | F7: Must | G7: 8 | H7: Sprint 2 | I7: Terminado
A8: HU-07 | B8: EP-04 Contratos | C8: RF-06 / RN-04 | D8: Como empresa quiero crear contratos por faena y que el sistema genere el checklist documental automáticamente | E8: Al crear un contrato se instancian los 10 requisitos de empresa | F8: Must | G8: 8 | H8: Sprint 2 | I8: Terminado
A9: HU-08 | B9: EP-04 Contratos | C9: RF-07 | D9: Como empresa quiero que el contrato herede las plataformas de acreditación de la faena para no configurarlas a mano | E9: El contrato hereda las plataformas de la faena y permite ajustarlas | F9: Must | G9: 8 | H9: Sprint 2 | I9: Terminado
A10: HU-09 | B10: EP-04 Contratos | C10: RF-09 / RN-06 | D10: Como empresa quiero agregar requisitos propios y ver la matriz de cumplimiento del contrato | E10: Requisitos custom sin duplicados; los requisitos base no se pueden borrar | F10: Should | G10: 5 | H10: Sprint 2 | I10: Terminado
A11: HU-10 | B11: EP-05 Personal y equipos | C11: RF-10 | D11: Como empresa quiero dar de alta trabajadores y equipos y que se generen sus requisitos según el cargo | E11: 13 requisitos de personal, 10 de equipo y 9 EMSIPOR para conductores; baja lógica | F11: Must | G11: 8 | H11: Sprint 2 | I11: Terminado
A12: HU-11 | B12: EP-05 Personal y equipos | C12: RF-11 | D12: Como empresa quiero ver a cada persona y equipo consolidado por RUT o patente para saber su estado en todos los contratos | E12: Vistas /personas y /flota agrupadas | F12: Could | G12: 3 | H12: Sprint 2 | I12: Terminado
A13: HU-12 | B13: EP-06 Gestión documental | C13: RF-12 / RN-03 | D13: Como empresa quiero subir y descargar documentos directamente a Azure Blob Storage para no pasar archivos por la API | E13: URLs SAS de subida y descarga con expiración; cada documento pertenece a un solo sujeto o contrato | F13: Must | G13: 8 | H13: Sprint 3 | I13: Terminado
A14: HU-13 | B14: EP-07 Vencimientos y alertas | C14: RF-13 / RN-02 | D14: Como empresa quiero que el sistema recalcule vencimientos a diario y me alerte para no perder acreditaciones | E14: Cron diario ok → por vencer → vencido; bandeja de alertas | F14: Must | G14: 8 | H14: Sprint 3 | I14: Terminado
A15: HU-14 | B15: EP-08 Revisión IA | C15: RF-14 | D15: Como empresa quiero que cada documento subido se revise con IA para detectar errores antes de enviarlo al mandante | E15: Job asíncrono; hallazgos clasificados como error, warning o info | F15: Must | G15: 8 | H15: Sprint 4 | I15: Terminado | J15: Modo simulado en desarrollo; modo real con LLM
A16: HU-15 | B16: EP-08 Revisión IA | C16: RF-15 | D16: Como empresa quiero que la IA lea contratos, cédulas y padrones para pre-llenar los formularios | E16: Extracción de contrato, sujeto y carpeta de arranque | F16: Should | G16: 5 | H16: Sprint 4 | I16: Terminado
A17: HU-16 | B17: EP-09 EMSIPOR / LIM | C17: RF-16 | D17: Como empresa quiero gestionar la licencia interna de mina y el expediente EMSIPOR de mis conductores | E17: Checklist de 9 documentos; número y vencimiento de la licencia | F17: Must | G17: 8 | H17: Sprint 4 | I17: Terminado
A18: HU-17 | B18: EP-10 Dashboard y calendario | C18: RF-17 | D18: Como empresa quiero ver KPIs, tendencia y un calendario de vencimientos para priorizar el trabajo | E18: Dashboard, cumplimiento por contrato, tendencia histórica y calendario | F18: Must | G18: 8 | H18: Sprint 4 | I18: Terminado
A19: HU-18 | B19: EP-11 Reportes y avisos | C19: RF-18 | D19: Como empresa quiero generar reportes PDF/Excel y recibir avisos por email y WhatsApp | E19: Reportes asíncronos y programados; preferencias de notificación | F19: Should | G19: 5 | H19: Sprint 5 | I19: Parcial | J19: Reportes listos; falta el envío real de email/WhatsApp
A20: HU-19 | B20: EP-12 Integraciones | C20: RF-19 | D20: Como empresa quiero sincronizar mis documentos con las plataformas del mandante (SIGA, Workmate…) | E20: Conectar, sincronizar y ver logs de cada integración | F20: Could | G20: 3 | H20: Sprint 5 | I20: Parcial | J20: Endpoints listos; falta guardar el secreto en Key Vault y el conector SIGA real
A21: HU-20 | B21: EP-04 Contratos | C21: RF-08 | D21: Como empresa quiero guardar mis credenciales de las plataformas del mandante cifradas para que nadie más pueda leerlas | E21: Cifrado JWE RSA-OAEP-256 + A256GCM; rotación con historial; la API no puede leer la columna | F21: Must | G21: 8 | H21: Sprint 6 | I21: Terminado
A22: HU-21 | B22: EP-13 Monetización | C22: RF-20 / RN-05 | D22: Como empresa quiero contratar un plan y ver mis facturas para mantener mi suscripción al día | E22: Planes, suscripción, facturas y webhook de pagos | F22: Should | G22: 5 | H22: Sprint 6 | I22: Parcial | J22: Falta conectar la pasarela de pago (Transbank o Stripe)
A23: HU-22 | B23: EP-14 Seguridad | C23: RNF-01 / RNF-02 | D23: Como empresa quiero que mis datos estén aislados de otras empresas incluso ante un error de programación | E23: RLS con FORCE ROW LEVEL SECURITY y rol de aplicación sin BYPASSRLS; pruebas de aislamiento | F23: Must | G23: 8 | H23: Sprint 6 | I23: Terminado
A24: HU-23 | B24: EP-14 Seguridad | C24: RNF-06 | D24: Como administrador quiero un registro de auditoría de las acciones para tener trazabilidad | E24: Tabla actividad append-only; consulta por empresa y contrato | F24: Should | G24: 5 | H24: Sprint 6 | I24: Terminado
A25: HU-24 | B25: EP-15 Consola Ops | C25: RF-21 | D25: Como administrador interno quiero una consola de operación y métricas financieras del SaaS | E25: Endpoints /admin/ops de salud, procesos e indicadores | F25: Won't | G25: 8 | H25: — | I25: Pendiente | J25: Fuera del alcance de esta versión (priorización MoSCoW)

Sheet Sprint Backlog
A1: Sprint | B1: Historia | C1: Tarea | D1: Detalle | E1: Endpoints / casos | F1: Responsable | G1: Estado
A2: Sprint 1 | B2: HU-01 | C2: Configurar docker-compose (Postgres 16, Redis, migrate, api, worker, beat, web) | G2: Terminado
A3: Sprint 1 | B3: HU-01 | C3: Job de migración del esquema con pg_advisory_lock (migrate/run.py) | G3: Terminado
A4: Sprint 1 | B4: HU-02 | C4: Implementar API de Autenticación (routers/auth.py) | D4: 8 endpoints | E4: 8 | G4: Terminado
A5: Sprint 1 | B5: HU-03 | C5: Implementar API de Administración (routers/admin.py) | D5: 13 endpoints | E5: 13 | G5: Terminado
A6: Sprint 1 | B6: HU-05 | C6: Implementar API de Empresa y usuarios (routers/company.py) | D6: 6 endpoints | E6: 6 | G6: Parcial
A7: Sprint 1 | B7: HU-04 | C7: Pruebas automatizadas: test_auth.py | D7: 28 casos de prueba | E7: 28 | G7: Terminado
A8: Sprint 1 | B8: HU-01 | C8: Frontend: login y layout con menú lateral | G8: Terminado
A9: Sprint 2 | B9: HU-06 | C9: Implementar API de Faenas (routers/faenas.py) | D9: 12 endpoints | E9: 12 | G9: Terminado
A10: Sprint 2 | B10: HU-06 | C10: Implementar API de Cargos (routers/cargos.py) | D10: 9 endpoints | E10: 9 | G10: Terminado
A11: Sprint 2 | B11: HU-06 | C11: Implementar API de Plantillas de requisitos (routers/requisitos.py) | D11: 2 endpoints | E11: 2 | G11: Terminado
A12: Sprint 2 | B12: HU-07 | C12: Implementar API de Contratos (routers/contratos.py) | D12: 12 endpoints | E12: 12 | G12: Terminado
A13: Sprint 2 | B13: HU-08 | C13: Implementar API de Plataformas del contrato (routers/plataformas.py) | D13: 11 endpoints | E13: 11 | G13: Terminado
A14: Sprint 2 | B14: HU-09 | C14: Implementar API de Checklist del contrato (routers/contrato_requisitos.py) | D14: 7 endpoints | E14: 7 | G14: Terminado
A15: Sprint 2 | B15: HU-10 | C15: Implementar API de Personal y equipos (routers/sujetos.py) | D15: 14 endpoints | E15: 14 | G15: Terminado
A16: Sprint 2 | B16: HU-11 | C16: Implementar API de Personas y flota (routers/personas.py) | D16: 4 endpoints | E16: 4 | G16: Terminado
A17: Sprint 2 | B17: HU-07 | C17: Pruebas automatizadas: test_contratos.py | D17: 28 casos de prueba | E17: 28 | G17: Terminado
A18: Sprint 2 | B18: HU-10 | C18: Pruebas automatizadas: test_sujetos.py | D18: 27 casos de prueba | E18: 27 | G18: Terminado
A19: Sprint 2 | B19: HU-10 | C19: Frontend: contratos, personal y equipos (listado y detalle), faenas | G19: Terminado
A20: Sprint 3 | B20: HU-12 | C20: Implementar API de Documentos (routers/documentos.py) | D20: 7 endpoints | E20: 7 | G20: Terminado
A21: Sprint 3 | B21: HU-12 | C21: Implementar API de Archivos SAS (routers/blobs.py) | D21: 2 endpoints | E21: 2 | G21: Terminado
A22: Sprint 3 | B22: HU-13 | C22: Implementar API de Alertas (routers/alertas.py) | D22: 4 endpoints | E22: 4 | G22: Terminado
A23: Sprint 3 | B23: HU-13 | C23: Cron diario de vencimientos (services/vencimientos.py) | G23: Terminado
A24: Sprint 3 | B24: HU-12 | C24: Pruebas automatizadas: test_documentos.py | D24: 25 casos de prueba | E24: 25 | G24: Terminado
A25: Sprint 3 | B25: HU-13 | C25: Frontend: alertas | G25: Terminado
A26: Sprint 4 | B26: HU-14 | C26: Implementar API de Revisión y extracción IA (routers/ia.py) | D26: 7 endpoints | E26: 7 | G26: Terminado
A27: Sprint 4 | B27: HU-14 | C27: Worker Celery para revisión IA (worker/celery_app.py, services/ia.py) | G27: Terminado
A28: Sprint 4 | B28: HU-16 | C28: Implementar API de Licencia interna EMSIPOR (routers/licencia_interna.py) | D28: 3 endpoints | E28: 3 | G28: Terminado
A29: Sprint 4 | B29: HU-17 | C29: Implementar API de Dashboard (routers/dashboard.py) | D29: 6 endpoints | E29: 6 | G29: Terminado
A30: Sprint 4 | B30: HU-17 | C30: Implementar API de Calendario (routers/calendario.py) | D30: 4 endpoints | E30: 4 | G30: Terminado
A31: Sprint 4 | B31: HU-17 | C31: Pruebas automatizadas: test_operacion.py | D31: 37 casos de prueba | E31: 37 | G31: Terminado
A32: Sprint 4 | B32: HU-17 | C32: Frontend: dashboard | G32: Terminado
A33: Sprint 5 | B33: HU-18 | C33: Implementar API de Reportes y exportaciones (routers/reportes.py) | D33: 9 endpoints | E33: 9 | G33: Terminado
A34: Sprint 5 | B34: HU-18 | C34: Implementar API de Preferencias de notificación (routers/notificaciones.py) | D34: 2 endpoints | E34: 2 | G34: Terminado
A35: Sprint 5 | B35: HU-18 | C35: Envío real de correo (SMTP) y WhatsApp | G35: Pendiente
A36: Sprint 5 | B36: HU-19 | C36: Implementar API de Integraciones (routers/integraciones.py) | D36: 6 endpoints | E36: 6 | G36: Parcial
A37: Sprint 5 | B37: HU-19 | C37: Escritura del secreto en Azure Key Vault y conector SIGA | G37: Pendiente
A38: Sprint 5 | B38: HU-18 | C38: Pruebas automatizadas: test_reportes.py | D38: 18 casos de prueba | E38: 18 | G38: Terminado
A39: Sprint 6 | B39: HU-21 | C39: Implementar API de Planes, suscripción y facturas (routers/suscripcion.py) | D39: 9 endpoints | E39: 9 | G39: Parcial
A40: Sprint 6 | B40: HU-21 | C40: Implementar API de Webhooks (pagos y WhatsApp) (routers/webhooks.py) | D40: 3 endpoints | E40: 3 | G40: Terminado
...

Sheet Sprints
A1: Sprint | B1: Inicio | C1: Término | D1: Objetivo del sprint | E1: Historias | F1: Puntos comprometidos | G1: Tareas | H1: Tareas terminadas | I1: Avance de tareas
A2: Sprint 1 | B2: 03-08-2026 | C2: 14-08-2026 | D2: Fundaciones: infraestructura, CI/CD, autenticación completa y esqueleto del frontend | E2: =COUNTIF('Product Backlog'!$H$2:$H$25,A2) -> 5 | F2: =SUMIF('Product Backlog'!$H$2:$H$25,A2,'Product Backlog'!$G$2:$G$25) -> 37 | G2: =COUNTIF('Sprint Backlog'!$A$2:$A$47,A2) -> 7 | H2: =COUNTIFS('Sprint Backlog'!$A$2:$A$47,A2,'Sprint Backlog'!$G$2:$G$47,"Terminado") -> 6 | I2: =IF(G2=0,"-",H2/G2) -> 0.85714286
A3: Sprint 2 | B3: 17-08-2026 | C3: 28-08-2026 | D3: Núcleo de negocio: catálogos, contratos, alta de personal y equipos con checklists | E3: =COUNTIF('Product Backlog'!$H$2:$H$25,A3) -> 6 | F3: =SUMIF('Product Backlog'!$H$2:$H$25,A3,'Product Backlog'!$G$2:$G$25) -> 40 | G3: =COUNTIF('Sprint Backlog'!$A$2:$A$47,A3) -> 11 | H3: =COUNTIFS('Sprint Backlog'!$A$2:$A$47,A3,'Sprint Backlog'!$G$2:$G$47,"Terminado") -> 11 | I3: =IF(G3=0,"-",H3/G3) -> 1
A4: Sprint 3 | B4: 31-08-2026 | C4: 11-09-2026 | D4: Ciclo documental: subida a Azure, estados, vencimientos y alertas | E4: =COUNTIF('Product Backlog'!$H$2:$H$25,A4) -> 2 | F4: =SUMIF('Product Backlog'!$H$2:$H$25,A4,'Product Backlog'!$G$2:$G$25) -> 16 | G4: =COUNTIF('Sprint Backlog'!$A$2:$A$47,A4) -> 6 | H4: =COUNTIFS('Sprint Backlog'!$A$2:$A$47,A4,'Sprint Backlog'!$G$2:$G$47,"Terminado") -> 6 | I4: =IF(G4=0,"-",H4/G4) -> 1
A5: Sprint 4 | B5: 14-09-2026 | C5: 25-09-2026 | D5: Inteligencia: revisión IA de documentos, módulo LIM y dashboard con KPIs | E5: =COUNTIF('Product Backlog'!$H$2:$H$25,A5) -> 4 | F5: =SUMIF('Product Backlog'!$H$2:$H$25,A5,'Product Backlog'!$G$2:$G$25) -> 29 | G5: =COUNTIF('Sprint Backlog'!$A$2:$A$47,A5) -> 7 | H5: =COUNTIFS('Sprint Backlog'!$A$2:$A$47,A5,'Sprint Backlog'!$G$2:$G$47,"Terminado") -> 7 | I5: =IF(G5=0,"-",H5/G5) -> 1
A6: Sprint 5 | B6: 28-09-2026 | C6: 09-10-2026 | D6: Salida al mundo: reportes, notificaciones (email/WhatsApp) e integración inicial SIGA | E6: =COUNTIF('Product Backlog'!$H$2:$H$25,A6) -> 2 | F6: =SUMIF('Product Backlog'!$H$2:$H$25,A6,'Product Backlog'!$G$2:$G$25) -> 8 | G6: =COUNTIF('Sprint Backlog'!$A$2:$A$47,A6) -> 6 | H6: =COUNTIFS('Sprint Backlog'!$A$2:$A$47,A6,'Sprint Backlog'!$G$2:$G$47,"Terminado") -> 3 | I6: =IF(G6=0,"-",H6/G6) -> 0.5
A7: Sprint 6 | B7: 12-10-2026 | C7: 23-10-2026 | D7: Monetización y cierre: suscripciones, pagos y endurecimiento de seguridad | E7: =COUNTIF('Product Backlog'!$H$2:$H$25,A7) -> 4 | F7: =SUMIF('Product Backlog'!$H$2:$H$25,A7,'Product Backlog'!$G$2:$G$25) -> 26 | G7: =COUNTIF('Sprint Backlog'!$A$2:$A$47,A7) -> 9 | H7: =COUNTIFS('Sprint Backlog'!$A$2:$A$47,A7,'Sprint Backlog'!$G$2:$G$47,"Terminado") -> 7 | I7: =IF(G7=0,"-",H7/G7) -> 0.77777778
A8: Total | E8: =SUM(E2:E7) -> 23 | F8: =SUM(F2:F7) -> 156 | G8: =SUM(G2:G7) -> 46 | H8: =SUM(H2:H7) -> 40 | I8: =IF(G8=0,"-",H8/G8) -> 0.86956522
A10: Estabilización | B10: 26-10-2026 | C10: 30-10-2026 | D10: Code freeze, corrección de defectos críticos, UAT y pase a producción
