Workbook

Sheet Portada
B8: Catálogo de Endpoints
B9: API REST FastAPI
B10: Acredittia
B12: Revisión: 1.0
B13: 30/10/2026
B15: Contenido del libro
B16: Resumen | D16: Endpoints por módulo y método HTTP
B17: Endpoints | D17: 161 endpoints con ruta, función y descripción
B19: Ficha del documento
B20: Fecha | C20: Revisión | D20: Autor | E20: Modificación
B21: 30/10/2026 | C21: 1.0 | D21: Equipo Acredittia | E21: Creación del documento
B24: Escuela de Informática y Telecomunicaciones · Duoc UC

Sheet Resumen
A1: Catálogo de endpoints — API Acredittia (FastAPI)
A2: Fuente: app/backend/app/routers/*.py del repositorio Backend_Acredita. Todas las rutas cuelgan de /api/v1.
A4: Módulo | B4: GET | C4: POST | D4: PUT | E4: PATCH | F4: DELETE | G4: Total
A5: Administración | B5: =COUNTIFS(Endpoints!$A$2:$A$162,$A5,Endpoints!$C$2:$C$162,"GET") -> 4 | C5: =COUNTIFS(Endpoints!$A$2:$A$162,$A5,Endpoints!$C$2:$C$162,"POST") -> 6 | D5: =COUNTIFS(Endpoints!$A$2:$A$162,$A5,Endpoints!$C$2:$C$162,"PUT") -> 0 | E5: =COUNTIFS(Endpoints!$A$2:$A$162,$A5,Endpoints!$C$2:$C$162,"PATCH") -> 2 | F5: =COUNTIFS(Endpoints!$A$2:$A$162,$A5,Endpoints!$C$2:$C$162,"DELETE") -> 1 | G5: =SUM(B5:F5) -> 13
A6: Alertas | B6: =COUNTIFS(Endpoints!$A$2:$A$162,$A6,Endpoints!$C$2:$C$162,"GET") -> 2 | C6: =COUNTIFS(Endpoints!$A$2:$A$162,$A6,Endpoints!$C$2:$C$162,"POST") -> 1 | D6: =COUNTIFS(Endpoints!$A$2:$A$162,$A6,Endpoints!$C$2:$C$162,"PUT") -> 0 | E6: =COUNTIFS(Endpoints!$A$2:$A$162,$A6,Endpoints!$C$2:$C$162,"PATCH") -> 1 | F6: =COUNTIFS(Endpoints!$A$2:$A$162,$A6,Endpoints!$C$2:$C$162,"DELETE") -> 0 | G6: =SUM(B6:F6) -> 4
A7: Archivos (SAS local) | B7: =COUNTIFS(Endpoints!$A$2:$A$162,$A7,Endpoints!$C$2:$C$162,"GET") -> 1 | C7: =COUNTIFS(Endpoints!$A$2:$A$162,$A7,Endpoints!$C$2:$C$162,"POST") -> 0 | D7: =COUNTIFS(Endpoints!$A$2:$A$162,$A7,Endpoints!$C$2:$C$162,"PUT") -> 1 | E7: =COUNTIFS(Endpoints!$A$2:$A$162,$A7,Endpoints!$C$2:$C$162,"PATCH") -> 0 | F7: =COUNTIFS(Endpoints!$A$2:$A$162,$A7,Endpoints!$C$2:$C$162,"DELETE") -> 0 | G7: =SUM(B7:F7) -> 2
A8: Auditoría | B8: =COUNTIFS(Endpoints!$A$2:$A$162,$A8,Endpoints!$C$2:$C$162,"GET") -> 1 | C8: =COUNTIFS(Endpoints!$A$2:$A$162,$A8,Endpoints!$C$2:$C$162,"POST") -> 0 | D8: =COUNTIFS(Endpoints!$A$2:$A$162,$A8,Endpoints!$C$2:$C$162,"PUT") -> 0 | E8: =COUNTIFS(Endpoints!$A$2:$A$162,$A8,Endpoints!$C$2:$C$162,"PATCH") -> 0 | F8: =COUNTIFS(Endpoints!$A$2:$A$162,$A8,Endpoints!$C$2:$C$162,"DELETE") -> 0 | G8: =SUM(B8:F8) -> 1
A9: Autenticación | B9: =COUNTIFS(Endpoints!$A$2:$A$162,$A9,Endpoints!$C$2:$C$162,"GET") -> 1 | C9: =COUNTIFS(Endpoints!$A$2:$A$162,$A9,Endpoints!$C$2:$C$162,"POST") -> 6 | D9: =COUNTIFS(Endpoints!$A$2:$A$162,$A9,Endpoints!$C$2:$C$162,"PUT") -> 0 | E9: =COUNTIFS(Endpoints!$A$2:$A$162,$A9,Endpoints!$C$2:$C$162,"PATCH") -> 1 | F9: =COUNTIFS(Endpoints!$A$2:$A$162,$A9,Endpoints!$C$2:$C$162,"DELETE") -> 0 | G9: =SUM(B9:F9) -> 8
A10: Calendario | B10: =COUNTIFS(Endpoints!$A$2:$A$162,$A10,Endpoints!$C$2:$C$162,"GET") -> 1 | C10: =COUNTIFS(Endpoints!$A$2:$A$162,$A10,Endpoints!$C$2:$C$162,"POST") -> 1 | D10: =COUNTIFS(Endpoints!$A$2:$A$162,$A10,Endpoints!$C$2:$C$162,"PUT") -> 0 | E10: =COUNTIFS(Endpoints!$A$2:$A$162,$A10,Endpoints!$C$2:$C$162,"PATCH") -> 1 | F10: =COUNTIFS(Endpoints!$A$2:$A$162,$A10,Endpoints!$C$2:$C$162,"DELETE") -> 1 | G10: =SUM(B10:F10) -> 4
A11: Cargos | B11: =COUNTIFS(Endpoints!$A$2:$A$162,$A11,Endpoints!$C$2:$C$162,"GET") -> 3 | C11: =COUNTIFS(Endpoints!$A$2:$A$162,$A11,Endpoints!$C$2:$C$162,"POST") -> 2 | D11: =COUNTIFS(Endpoints!$A$2:$A$162,$A11,Endpoints!$C$2:$C$162,"PUT") -> 0 | E11: =COUNTIFS(Endpoints!$A$2:$A$162,$A11,Endpoints!$C$2:$C$162,"PATCH") -> 2 | F11: =COUNTIFS(Endpoints!$A$2:$A$162,$A11,Endpoints!$C$2:$C$162,"DELETE") -> 2 | G11: =SUM(B11:F11) -> 9
A12: Checklist del contrato | B12: =COUNTIFS(Endpoints!$A$2:$A$162,$A12,Endpoints!$C$2:$C$162,"GET") -> 2 | C12: =COUNTIFS(Endpoints!$A$2:$A$162,$A12,Endpoints!$C$2:$C$162,"POST") -> 2 | D12: =COUNTIFS(Endpoints!$A$2:$A$162,$A12,Endpoints!$C$2:$C$162,"PUT") -> 1 | E12: =COUNTIFS(Endpoints!$A$2:$A$162,$A12,Endpoints!$C$2:$C$162,"PATCH") -> 1 | F12: =COUNTIFS(Endpoints!$A$2:$A$162,$A12,Endpoints!$C$2:$C$162,"DELETE") -> 1 | G12: =SUM(B12:F12) -> 7
A13: Contratos | B13: =COUNTIFS(Endpoints!$A$2:$A$162,$A13,Endpoints!$C$2:$C$162,"GET") -> 8 | C13: =COUNTIFS(Endpoints!$A$2:$A$162,$A13,Endpoints!$C$2:$C$162,"POST") -> 2 | D13: =COUNTIFS(Endpoints!$A$2:$A$162,$A13,Endpoints!$C$2:$C$162,"PUT") -> 0 | E13: =COUNTIFS(Endpoints!$A$2:$A$162,$A13,Endpoints!$C$2:$C$162,"PATCH") -> 1 | F13: =COUNTIFS(Endpoints!$A$2:$A$162,$A13,Endpoints!$C$2:$C$162,"DELETE") -> 1 | G13: =SUM(B13:F13) -> 12
A14: Dashboard | B14: =COUNTIFS(Endpoints!$A$2:$A$162,$A14,Endpoints!$C$2:$C$162,"GET") -> 6 | C14: =COUNTIFS(Endpoints!$A$2:$A$162,$A14,Endpoints!$C$2:$C$162,"POST") -> 0 | D14: =COUNTIFS(Endpoints!$A$2:$A$162,$A14,Endpoints!$C$2:$C$162,"PUT") -> 0 | E14: =COUNTIFS(Endpoints!$A$2:$A$162,$A14,Endpoints!$C$2:$C$162,"PATCH") -> 0 | F14: =COUNTIFS(Endpoints!$A$2:$A$162,$A14,Endpoints!$C$2:$C$162,"DELETE") -> 0 | G14: =SUM(B14:F14) -> 6
A15: Documentos | B15: =COUNTIFS(Endpoints!$A$2:$A$162,$A15,Endpoints!$C$2:$C$162,"GET") -> 3 | C15: =COUNTIFS(Endpoints!$A$2:$A$162,$A15,Endpoints!$C$2:$C$162,"POST") -> 2 | D15: =COUNTIFS(Endpoints!$A$2:$A$162,$A15,Endpoints!$C$2:$C$162,"PUT") -> 0 | E15: =COUNTIFS(Endpoints!$A$2:$A$162,$A15,Endpoints!$C$2:$C$162,"PATCH") -> 1 | F15: =COUNTIFS(Endpoints!$A$2:$A$162,$A15,Endpoints!$C$2:$C$162,"DELETE") -> 1 | G15: =SUM(B15:F15) -> 7
A16: Empresa | B16: =COUNTIFS(Endpoints!$A$2:$A$162,$A16,Endpoints!$C$2:$C$162,"GET") -> 2 | C16: =COUNTIFS(Endpoints!$A$2:$A$162,$A16,Endpoints!$C$2:$C$162,"POST") -> 1 | D16: =COUNTIFS(Endpoints!$A$2:$A$162,$A16,Endpoints!$C$2:$C$162,"PUT") -> 0 | E16: =COUNTIFS(Endpoints!$A$2:$A$162,$A16,Endpoints!$C$2:$C$162,"PATCH") -> 2 | F16: =COUNTIFS(Endpoints!$A$2:$A$162,$A16,Endpoints!$C$2:$C$162,"DELETE") -> 1 | G16: =SUM(B16:F16) -> 6
... A28: Webhooks | B28: =COUNTIFS(Endpoints!$A$2:$A$162,$A28,Endpoints!$C$2:$C$162,"GET") -> 1 | C28: =COUNTIFS(Endpoints!$A$2:$A$162,$A28,Endpoints!$C$2:$C$162,"POST") -> 2 | D28: =COUNTIFS(Endpoints!$A$2:$A$162,$A28,Endpoints!$C$2:$C$162,"PUT") -> 0 | E28: =COUNTIFS(Endpoints!$A$2:$A$162,$A28,Endpoints!$C$2:$C$162,"PATCH") -> 0 | F28: =COUNTIFS(Endpoints!$A$2:$A$162,$A28,Endpoints!$C$2:$C$162,"DELETE") -> 0 | G28: =SUM(B28:F28) -> 3
A29: Total | B29: =SUM(B5:B28) -> 76 | C29: =SUM(C5:C28) -> 46 | D29: =SUM(D5:D28) -> 2 | E29: =SUM(E5:E28) -> 22 | F29: =SUM(F5:F28) -> 15 | G29: =SUM(G5:G28) -> 161

Sheet Endpoints
A1: Módulo | B1: Archivo | C1: Método | D1: Ruta | E1: Función | F1: Descripción (docstring)
A2: Administración | B2: routers/admin.py | C2: GET | D2: /api/v1/admin/companies | E2: list_companies | F2: Solicitudes y cuentas de empresa, la más reciente primero.
A3: Administración | B3: routers/admin.py | C3: GET | D3: /api/v1/admin/companies/{company_id} | E3: detalle_company | F3: Ficha de una empresa con sus estadísticas de operación.
A4: Administración | B4: routers/admin.py | C4: POST | D4: /api/v1/admin/companies/{company_id}/approve | E4: approve
A5: Administración | B5: routers/admin.py | C5: POST | D5: /api/v1/admin/companies/{company_id}/reject | E5: reject
A6: Administración | B6: routers/admin.py | C6: POST | D6: /api/v1/admin/companies/{company_id}/reset-demo | E6: reset_demo | F6: Reinicia los datos de operación de una empresa demo. Irreversible.
A7: Administración | B7: routers/admin.py | C7: POST | D7: /api/v1/admin/faenas | E7: crear_faena | F7: Da de alta una faena en el catálogo global.
A8: Administración | B8: routers/admin.py | C8: PATCH | D8: /api/v1/admin/faenas/{faena_id} | E8: editar_faena | F8: Edita los datos y el branding de una faena del catálogo.
A9: Administración | B9: routers/admin.py | C9: POST | D9: /api/v1/admin/faenas/{faena_id}/plataformas | E9: crear_plataforma_faena | F9: Agrega una plataforma del mandante a la faena (SIGA, DIRECTIC, …).
A10: Administración | B10: routers/admin.py | C10: GET | D10: /api/v1/admin/requisitos/templates | E10: listar_templates | F10: Catálogo completo de plantillas, incluidas las inactivas.
A11: Administración | B11: routers/admin.py | C11: POST | D11: /api/v1/admin/requisitos/templates | E11: crear_template | F11: Crea una plantilla de requisito.
A12: Administración | B12: routers/admin.py | C12: DELETE | D12: /api/v1/admin/requisitos/templates/{template_id} | E12: eliminar_template | F12: Desactiva la plantilla (borrado en blando). Nunca borra documentos.
A13: Administración | B13: routers/admin.py | C13: PATCH | D13: /api/v1/admin/requisitos/templates/{template_id} | E13: editar_template | F13: Edita una plantilla. Los cambios NO se propagan a lo ya instanciado.
A14: Administración | B14: routers/admin.py | C14: GET | D14: /api/v1/admin/stats | E14: stats | F14: KPI de la plataforma.
A15: Alertas | B15: routers/alertas.py | C15: GET | D15: /api/v1/alertas | E15: listar | F15: Alertas de la empresa, la más reciente primero.
A16: Alertas | B16: routers/alertas.py | C16: POST | D16: /api/v1/alertas/marcar-leidas | E16: marcar_leidas | F16: Marca como leídas las alertas indicadas, o todas las no leídas.
A17: Alertas | B17: routers/alertas.py | C17: GET | D17: /api/v1/alertas/resumen | E17: resumen | F17: Contadores de la campana de notificaciones.
... A22: Autenticación | B22: routers/auth.py | C22: POST | D22: /api/v1/auth/login | E22: login | F22: Emite el par de tokens. Rechaza cuentas no aprobadas o desactivadas.
A23: Autenticación | B23: routers/auth.py | C23: POST | D23: /api/v1/auth/logout | E23: logout
A24: Autenticación | B24: routers/auth.py | C24: GET | D24: /api/v1/auth/me | E24: me | F24: Perfil del usuario autenticado.
A25: Autenticación | B25: routers/auth.py | C25: PATCH | D25: /api/v1/auth/me | E25: editar_me | F25: Autoservicio del perfil: nombre, email y contraseña.
A26: Autenticación | B26: routers/auth.py | C26: POST | D26: /api/v1/auth/password/forgot | E26: password_forgot | F26: Emite un token de restablecimiento. Respuesta idéntica exista o no la cuenta.
A27: Autenticación | B27: routers/auth.py | C27: POST | D27: /api/v1/auth/password/reset | E27: password_reset | F27: Consume un token de restablecimiento y cambia la contraseña.
A28: Autenticación | B28: routers/auth.py | C28: POST | D28: /api/v1/auth/refresh | E28: refresh | F28: Rota el refresh token. Sin tenant en contexto: ver `login`.
A29: Autenticación | B29: routers/auth.py | C29: POST | D29: /api/v1/auth/register | E29: register | F29: Alta de una empresa y de su primer usuario, en estado `pending`.
A30: Calendario | B30: routers/calendario.py | C30: GET | D30: /api/v1/calendario/eventos | E30: listar_eventos | F30: Eventos del rango: vencimientos proyectados + anotaciones de la empresa.
A31: Calendario | B31: routers/calendario.py | C31: POST | D31: /api/v1/calendario/eventos | E31: crear_evento | F31: Anota un evento propio de la empresa en el calendario.
A32: Calendario | B32: routers/calendario.py | C32: DELETE | D32: /api/v1/calendario/eventos/{evento_id} | E32: eliminar_evento | F32: Elimina un evento manual. Los vencimientos no se pueden borrar: no son
A33: Calendario | B33: routers/calendario.py | C33: PATCH | D33: /api/v1/calendario/eventos/{evento_id} | E33: editar_evento | F33: Edita un evento manual. La categoría sigue sin poder ser 'vencimiento'.
A34: Cargos | B34: routers/cargos.py | C34: GET | D34: /api/v1/admin/cargos | E34: admin_listar | F34: Catálogo base de Acredittia, el que heredan todas las empresas.
A35: Cargos | B35: routers/cargos.py | C35: POST | D35: /api/v1/admin/cargos | E35: admin_crear | F35: Crea un cargo del catálogo base (company_id NULL).
... A53: Contratos | B53: routers/contratos.py | C53: DELETE | D53: /api/v1/contratos/{contrato_id} | E53: eliminar | F53: Borra el contrato y todo lo que cuelga de él. Exige confirm con dotación.
A54: Contratos | B54: routers/contratos.py | C54: GET | D54: /api/v1/contratos/{contrato_id} | E54: detalle
A55: Contratos | B55: routers/contratos.py | C55: PATCH | D55: /api/v1/contratos/{contrato_id} | E55: editar
A56: Contratos | B56: routers/contratos.py | C56: GET | D56: /api/v1/contratos/{contrato_id}/alertas | E56: alertas_contrato | F56: Alertas del contrato, en el mismo formato que `GET /alertas`.
A57: Contratos | B57: routers/contratos.py | C57: GET | D57: /api/v1/contratos/{contrato_id}/documentos | E57: docs_empresa | F57: Checklist de ámbito empresa del contrato (los que cuelgan del contrato).
A58: Contratos | B58: routers/contratos.py | C58: GET | D58: /api/v1/contratos/{contrato_id}/equipos | E58: equipos_contrato | F58: Flota del contrato. Mismos filtros y formato que `GET /equipos`.
A59: Contratos | B59: routers/contratos.py | C59: GET | D59: /api/v1/contratos/{contrato_id}/historial | E59: historial_contrato | F59: Actividad relacionada con el contrato, la más reciente primero.
A60: Contratos | B60: routers/contratos.py | C60: GET | D60: /api/v1/contratos/{contrato_id}/matriz | E60: matriz | F60: Matriz dispersa sujeto × requisito del contrato (§8.4).
A61: Contratos | B61: routers/contratos.py | C61: GET | D61: /api/v1/contratos/{contrato_id}/personal | E61: personal_contrato | F61: Personal del contrato. Mismos filtros y formato que `GET /personal`.
...
