Workbook

Sheet Portada
B8: Casos de Prueba
B9: Suite automatizada del backend
B10: Acredittia
B12: Revisión: 1.0
B13: 30/10/2026
B15: Contenido del libro
B16: Resumen | D16: Casos y resultados por módulo
B17: Casos de prueba | D17: 206 casos con requisito, precondiciones, pasos y resultado esperado
B19: Ficha del documento
B20: Fecha | C20: Revisión | D20: Autor | E20: Modificación
B21: 30/10/2026 | C21: 1.0 | D21: Equipo Acredittia | E21: Creación del documento
B24: Escuela de Informática y Telecomunicaciones · Duoc UC

Sheet Resumen
A1: Casos de prueba — Acredittia (backend)
A2: Fuente: suite pytest de Backend_Acredita (app/backend/tests). Cada caso corresponde a una función de prueba automatizada.
A4: Módulo | B4: Casos | C4: Variantes ejecutadas | D4: Aprobados | E4: Fallidos | F4: Omitidos | G4: Pendientes
A5: Autenticación y cuentas | B5: =COUNTIF('Casos de prueba'!$B$2:$B$207,A5) -> 28 | C5: =SUMIF('Casos de prueba'!$B$2:$B$207,A5,'Casos de prueba'!$J$2:$J$207) -> 32 | D5: =COUNTIFS('Casos de prueba'!$B$2:$B$207,$A5,'Casos de prueba'!$N$2:$N$207,"Aprobado") -> 0 | E5: =COUNTIFS('Casos de prueba'!$B$2:$B$207,$A5,'Casos de prueba'!$N$2:$N$207,"Fallido") -> 0 | F5: =COUNTIFS('Casos de prueba'!$B$2:$B$207,$A5,'Casos de prueba'!$N$2:$N$207,"Omitido") -> 0 | G5: =COUNTIFS('Casos de prueba'!$B$2:$B$207,$A5,'Casos de prueba'!$N$2:$N$207,"Pendiente") -> 28
A6: Contratos y requisitos | B6: =COUNTIF('Casos de prueba'!$B$2:$B$207,A6) -> 28 | C6: =SUMIF('Casos de prueba'!$B$2:$B$207,A6,'Casos de prueba'!$J$2:$J$207) -> 32 | D6: =COUNTIFS('Casos de prueba'!$B$2:$B$207,$A6,'Casos de prueba'!$N$2:$N$207,"Aprobado") -> 0 | E6: =COUNTIFS('Casos de prueba'!$B$2:$B$207,$A6,'Casos de prueba'!$N$2:$N$207,"Fallido") -> 0 | F6: =COUNTIFS('Casos de prueba'!$B$2:$B$207,$A6,'Casos de prueba'!$N$2:$N$207,"Omitido") -> 0 | G6: =COUNTIFS('Casos de prueba'!$B$2:$B$207,$A6,'Casos de prueba'!$N$2:$N$207,"Pendiente") -> 28
A7: Gestión documental e IA | B7: =COUNTIF('Casos de prueba'!$B$2:$B$207,A7) -> 25 | C7: =SUMIF('Casos de prueba'!$B$2:$B$207,A7,'Casos de prueba'!$J$2:$J$207) -> 29 | D7: =COUNTIFS('Casos de prueba'!$B$2:$B$207,$A7,'Casos de prueba'!$N$2:$N$207,"Aprobado") -> 0 | E7: =COUNTIFS('Casos de prueba'!$B$2:$B$207,$A7,'Casos de prueba'!$N$2:$N$207,"Fallido") -> 0 | F7: =COUNTIFS('Casos de prueba'!$B$2:$B$207,$A7,'Casos de prueba'!$N$2:$N$207,"Omitido") -> 0 | G7: =COUNTIFS('Casos de prueba'!$B$2:$B$207,$A7,'Casos de prueba'!$N$2:$N$207,"Pendiente") -> 25
A8: Esquema de base de datos | B8: =COUNTIF('Casos de prueba'!$B$2:$B$207,A8) -> 9 | C8: =SUMIF('Casos de prueba'!$B$2:$B$207,A8,'Casos de prueba'!$J$2:$J$207) -> 9 | D8: =COUNTIFS('Casos de prueba'!$B$2:$B$207,$A8,'Casos de prueba'!$N$2:$N$207,"Aprobado") -> 0 | E8: =COUNTIFS('Casos de prueba'!$B$2:$B$207,$A8,'Casos de prueba'!$N$2:$N$207,"Fallido") -> 0 | F8: =COUNTIFS('Casos de prueba'!$B$2:$B$207,$A8,'Casos de prueba'!$N$2:$N$207,"Omitido") -> 0 | G8: =COUNTIFS('Casos de prueba'!$B$2:$B$207,$A8,'Casos de prueba'!$N$2:$N$207,"Pendiente") -> 9
A9: Alertas, dashboard y calendario | B9: =COUNTIF('Casos de prueba'!$B$2:$B$207,A9) -> 37 | C9: =SUMIF('Casos de prueba'!$B$2:$B$207,A9,'Casos de prueba'!$J$2:$J$207) -> 47 | D9: =COUNTIFS('Casos de prueba'!$B$2:$B$207,$A9,'Casos de prueba'!$N$2:$N$207,"Aprobado") -> 0 | E9: =COUNTIFS('Casos de prueba'!$B$2:$B$207,$A9,'Casos de prueba'!$N$2:$N$207,"Fallido") -> 0 | F9: =COUNTIFS('Casos de prueba'!$B$2:$B$207,$A9,'Casos de prueba'!$N$2:$N$207,"Omitido") -> 0 | G9: =COUNTIFS('Casos de prueba'!$B$2:$B$207,$A9,'Casos de prueba'!$N$2:$N$207,"Pendiente") -> 37
A10: Reportes y exportaciones | B10: =COUNTIF('Casos de prueba'!$B$2:$B$207,A10) -> 18 | C10: =SUMIF('Casos de prueba'!$B$2:$B$207,A10,'Casos de prueba'!$J$2:$J$207) -> 30 | D10: =COUNTIFS('Casos de prueba'!$B$2:$B$207,$A10,'Casos de prueba'!$N$2:$N$207,"Aprobado") -> 0 | E10: =COUNTIFS('Casos de prueba'!$B$2:$B$207,$A10,'Casos de prueba'!$N$2:$N$207,"Fallido") -> 0 | F10: =COUNTIFS('Casos de prueba'!$B$2:$B$207,$A10,'Casos de prueba'!$N$2:$N$207,"Omitido") -> 0 | G10: =COUNTIFS('Casos de prueba'!$B$2:$B$207,$A10,'Casos de prueba'!$N$2:$N$207,"Pendiente") -> 18
A11: Personal, equipos y EMSIPOR | B11: =COUNTIF('Casos de prueba'!$B$2:$B$207,A11) -> 27 | C11: =SUMIF('Casos de prueba'!$B$2:$B$207,A11,'Casos de prueba'!$J$2:$J$207) -> 28 | D11: =COUNTIFS('Casos de prueba'!$B$2:$B$207,$A11,'Casos de prueba'!$N$2:$N$207,"Aprobado") -> 0 | E11: =COUNTIFS('Casos de prueba'!$B$2:$B$207,$A11,'Casos de prueba'!$N$2:$N$207,"Fallido") -> 0 | F11: =COUNTIFS('Casos de prueba'!$B$2:$B$207,$A11,'Casos de prueba'!$N$2:$N$207,"Omitido") -> 0 | G11: =COUNTIFS('Casos de prueba'!$B$2:$B$207,$A11,'Casos de prueba'!$N$2:$N$207,"Pendiente") -> 27
A12: Aislamiento multi-tenant | B12: =COUNTIF('Casos de prueba'!$B$2:$B$207,A12) -> 14 | C12: =SUMIF('Casos de prueba'!$B$2:$B$207,A12,'Casos de prueba'!$J$2:$J$207) -> 14 | D12: =COUNTIFS('Casos de prueba'!$B$2:$B$207,$A12,'Casos de prueba'!$N$2:$N$207,"Aprobado") -> 0 | E12: =COUNTIFS('Casos de prueba'!$B$2:$B$207,$A12,'Casos de prueba'!$N$2:$N$207,"Fallido") -> 0 | F12: =COUNTIFS('Casos de prueba'!$B$2:$B$207,$A12,'Casos de prueba'!$N$2:$N$207,"Omitido") -> 0 | G12: =COUNTIFS('Casos de prueba'!$B$2:$B$207,$A12,'Casos de prueba'!$N$2:$N$207,"Pendiente") -> 14
A13: Bóveda de credenciales JWE | B13: =COUNTIF('Casos de prueba'!$B$2:$B$207,A13) -> 20 | C13: =SUMIF('Casos de prueba'!$B$2:$B$207,A13,'Casos de prueba'!$J$2:$J$207) -> 20 | D13: =COUNTIFS('Casos de prueba'!$B$2:$B$207,$A13,'Casos de prueba'!$N$2:$N$207,"Aprobado") -> 0 | E13: =COUNTIFS('Casos de prueba'!$B$2:$B$207,$A13,'Casos de prueba'!$N$2:$N$207,"Fallido") -> 0 | F13: =COUNTIFS('Casos de prueba'!$B$2:$B$207,$A13,'Casos de prueba'!$N$2:$N$207,"Omitido") -> 0 | G13: =COUNTIFS('Casos de prueba'!$B$2:$B$207,$A13,'Casos de prueba'!$N$2:$N$207,"Pendiente") -> 20
A14: Total | B14: =SUM(B5:B13) -> 206 | C14: =SUM(C5:C13) -> 241 | D14: =SUM(D5:D13) -> 0 | E14: =SUM(E5:E13) -> 0 | F14: =SUM(F5:F13) -> 0 | G14: =SUM(G5:G13) -> 206
A16: Tasa de aprobación | B16: =IF(B14-G14=0,"-",D14/(B14-G14)) -> -
A18: Columnas 'Resultado obtenido' y 'Estado': se completan con la ejecución de la suite (ver Resultados de pruebas).

Sheet Casos de prueba
A1: ID | B1: Módulo | C1: Requisito | D1: Tipo | E1: Caso de prueba | F1: Objetivo | G1: Precondiciones | H1: Pasos (endpoints) | I1: Resultado esperado | J1: Variantes | K1: Verificaciones | L1: Ubicación en el código | M1: Resultado obtenido | N1: Estado
A2: CP-AUT-01 | B2: Autenticación y cuentas | C2: RF-01 | D2: Integración (API) | E2: Registro queda pendiente | G2: API levantada sobre PostgreSQL 16 | H2: POST /api/v1/auth/register · POST /api/v1/auth/login | I2: Registro queda pendiente. HTTP 201, 403 ; código de error ACCOUNT_PENDING. | J2: 1 | K2: 5 | L2: tests/test_auth.py::test_registro_queda_pendiente | N2: Pendiente
A3: CP-AUT-02 | B3: Autenticación y cuentas | C3: RF-01 | D3: Integración (API) | E3: Registro email y rut duplicados | G3: API levantada sobre PostgreSQL 16; Empresa A registrada, aprobada y autenticada | H3: POST /api/v1/auth/register | I3: Registro email y rut duplicados. HTTP 409 ; código de error EMAIL_EN_USO, RUT_EN_USO. | J3: 1 | K3: 4 | L3: tests/test_auth.py::test_registro_email_y_rut_duplicados | N3: Pendiente
A4: CP-AUT-03 | B4: Autenticación y cuentas | C4: RF-01 | D4: Integración (API) | E4: Registro rut invalido | G4: API levantada sobre PostgreSQL 16 | H4: POST /api/v1/auth/register | I4: Registro rut invalido. HTTP 422 ; código de error RUT_INVALIDO. | J4: 1 | K4: 2 | L4: tests/test_auth.py::test_registro_rut_invalido | N4: Pendiente
A5: CP-AUT-04 | B5: Autenticación y cuentas | C5: RF-01 | D5: Integración (API) | E5: Registro rechaza password debil | G5: API levantada sobre PostgreSQL 16 | H5: POST /api/v1/auth/register | I5: Registro rechaza password debil. HTTP 422 ; código de error PASSWORD_DEBIL. | J5: 3 | K5: 2 | L5: tests/test_auth.py::test_registro_rechaza_password_debil | N5: Pendiente
A6: CP-AUT-05 | B6: Autenticación y cuentas | C6: RF-03 | D6: Integración (API) | E6: Login y me | G6: API levantada sobre PostgreSQL 16; Empresa A registrada, aprobada y autenticada | H6: GET /api/v1/auth/me | I6: Login y me. HTTP 200. | J6: 1 | K6: 7 | L6: tests/test_auth.py::test_login_y_me | N6: Pendiente
A7: CP-AUT-06 | B7: Autenticación y cuentas | C7: RF-03 | D7: Integración (API) | E7: Me sin token | G7: API levantada sobre PostgreSQL 16 | H7: GET /api/v1/auth/me | I7: Me sin token. HTTP 401 ; código de error TOKEN_AUSENTE, TOKEN_INVALIDO. | J7: 1 | K7: 4 | L7: tests/test_auth.py::test_me_sin_token | N7: Pendiente
A8: CP-AUT-07 | B8: Autenticación y cuentas | C8: RF-03 | D8: Integración (API) | E8: Login credenciales invalidas | G8: API levantada sobre PostgreSQL 16; Empresa A registrada, aprobada y autenticada | H8: POST /api/v1/auth/login | I8: Login credenciales invalidas. HTTP 401 ; código de error CREDENCIALES_INVALIDAS. | J8: 1 | K8: 2 | L8: tests/test_auth.py::test_login_credenciales_invalidas | N8: Pendiente
A9: CP-AUT-08 | B9: Autenticación y cuentas | C9: RF-04 | D9: Integración (API) | E9: Login usuario desactivado | F9: `activo=False` no es lo mismo que rechazado: 403 CUENTA_DESACTIVADA. | G9: API levantada sobre PostgreSQL 16; Empresa A registrada, aprobada y autenticada | H9: POST /api/v1/auth/login · GET /api/v1/auth/me | I9: Login usuario desactivado. HTTP 403, 401 ; código de error CUENTA_DESACTIVADA. | J9: 1 | K9: 3 | L9: tests/test_auth.py::test_login_usuario_desactivado | N9: Pendiente
A10: CP-AUT-09 | B10: Autenticación y cuentas | C10: RF-02 | D10: Integración (API) | E10: Login rechazado | G10: API levantada sobre PostgreSQL 16; Usuario administrador de la plataforma | H10: POST /api/v1/auth/register · POST /api/v1/admin/companies/{id}/reject · POST /api/v1/auth/login | I10: Login rechazado. HTTP 200, 403 ; código de error ACCOUNT_REJECTED. | J10: 1 | K10: 3 | L10: tests/test_auth.py::test_login_rechazado | N10: Pendiente
A11: CP-AUT-10 | B11: Autenticación y cuentas | C11: RF-03 | D11: Integración (API) | E11: Refresh rota el token | G11: API levantada sobre PostgreSQL 16; Empresa A registrada, aprobada y autenticada | H11: POST /api/v1/auth/refresh · GET /api/v1/auth/me | I11: Refresh rota el token. HTTP 200, 401 ; código de error REFRESH_INVALIDO. | J11: 1 | K11: 6 | L11: tests/test_auth.py::test_refresh_rota_el_token | N11: Pendiente
A12: CP-AUT-11 | B12: Autenticación y cuentas | C12: RF-04 | D12: Integración (API) | E12: Refresh de usuario desactivado | G12: API levantada sobre PostgreSQL 16; Empresa A registrada, aprobada y autenticada | H12: POST /api/v1/auth/refresh | I12: Refresh de usuario desactivado. HTTP 401 ; código de error REFRESH_INVALIDO. | J12: 1 | K12: 2 | L12: tests/test_auth.py::test_refresh_de_usuario_desactivado | N12: Pendiente
A13: CP-AUT-12 | B13: Autenticación y cuentas | C13: RF-03 | D13: Integración (API) | E13: Logout revoca el refresh | G13: API levantada sobre PostgreSQL 16; Empresa A registrada, aprobada y autenticada | H13: POST /api/v1/auth/logout · POST /api/v1/auth/refresh | I13: Logout revoca el refresh. HTTP 200, 401. | J13: 1 | K13: 2 | L13: tests/test_auth.py::test_logout_revoca_el_refresh | N13: Pendiente
A14: CP-AUT-13 | B14: Autenticación y cuentas | C14: RF-03 | D14: Integración (API) | E14: Forgot es opaco | G14: API levantada sobre PostgreSQL 16; Empresa A registrada, aprobada y autenticada | H14: POST /api/v1/auth/password/forgot | I14: Forgot es opaco. HTTP 200. | J14: 1 | K14: 3 | L14: tests/test_auth.py::test_forgot_es_opaco | N14: Pendiente
A15: CP-AUT-14 | B15: Autenticación y cuentas | C15: RF-03 | D15: Integración (API) | E15: Forgot invalida el token anterior | G15: API levantada sobre PostgreSQL 16; Empresa A registrada, aprobada y autenticada | H15: POST /api/v1/auth/password/forgot · POST /api/v1/auth/password/reset | I15: Forgot invalida el token anterior. HTTP 400, 200 ; código de error TOKEN_INVALIDO. | J15: 1 | K15: 4 | L15: tests/test_auth.py::test_forgot_invalida_el_token_anterior | N15: Pendiente
A16: CP-AUT-15 | B16: Autenticación y cuentas | C16: RF-03 / RNF-03 | D16: Integración (API) | E16: Reset cambia la clave y revoca sesiones | G16: API levantada sobre PostgreSQL 16; Empresa A registrada, aprobada y autenticada | H16: POST /api/v1/auth/password/forgot · POST /api/v1/auth/password/reset · POST /api/v1/auth/login · POST /api/v1/auth/refresh | I16: Reset cambia la clave y revoca sesiones. HTTP 200, 401, 400. | J16: 1 | K16: 6 | L16: tests/test_auth.py::test_reset_cambia_la_clave_y_revoca_sesiones | N16: Pendiente
A17: CP-AUT-16 | B17: Autenticación y cuentas | C17: RF-03 / RNF-03 | D17: Integración (API) | E17: Reset aplica politica de password | G17: API levantada sobre PostgreSQL 16; Empresa A registrada, aprobada y autenticada | H17: POST /api/v1/auth/password/forgot · POST /api/v1/auth/password/reset | I17: Reset aplica politica de password. HTTP 400 ; código de error PASSWORD_DEBIL. | J17: 3 | K17: 2 | L17: tests/test_auth.py::test_reset_aplica_politica_de_password | N17: Pendiente
A18: CP-AUT-17 | B18: Autenticación y cuentas | C18: RF-03 / RNF-03 | D18: Integración (API) | E18: Reset con token inexistente | G18: API levantada sobre PostgreSQL 16 | H18: POST /api/v1/auth/password/reset | I18: Reset con token inexistente. HTTP 400 ; código de error TOKEN_INVALIDO. | J18: 1 | K18: 2 | L18: tests/test_auth.py::test_reset_con_token_inexistente | N18: Pendiente
A19: CP-AUT-18 | B19: Autenticación y cuentas | C19: RF-03 | D19: Integración (API) | E19: Patch me cuerpo vacio | G19: API levantada sobre PostgreSQL 16; Empresa A registrada, aprobada y autenticada | H19: PATCH /api/v1/auth/me | I19: Patch me cuerpo vacio. HTTP 400 ; código de error SIN_CAMBIOS. | J19: 1 | K19: 2 | L19: tests/test_auth.py::test_patch_me_cuerpo_vacio | N19: Pendiente
A20: CP-AUT-19 | B20: Autenticación y cuentas | C20: RF-03 | D20: Integración (API) | E20: Patch me nombre y email | G20: API levantada sobre PostgreSQL 16; Empresa A registrada, aprobada y autenticada | H20: PATCH /api/v1/auth/me · POST /api/v1/auth/login | I20: Patch me nombre y email. HTTP 200. | J20: 1 | K20: 5 | L20: tests/test_auth.py::test_patch_me_nombre_y_email | N20: Pendiente
A21: CP-AUT-20 | B21: Autenticación y cuentas | C21: RF-03 | D21: Integración (API) | E21: Patch me email en uso | F21: El email es único a nivel de plataforma, aunque RLS oculte al otro usuario. | G21: API levantada sobre PostgreSQL 16; Empresa A registrada, aprobada y autenticada; Empresa B registrada, aprobada y autenticada | H21: PATCH /api/v1/auth/me | I21: Patch me email en uso. HTTP 409 ; código de error EMAIL_EN_USO. | J21: 1 | K21: 2 | L21: tests/test_auth.py::test_patch_me_email_en_uso | N21: Pendiente
A22: CP-AUT-21 | B22: Autenticación y cuentas | C22: RF-03 / RNF-03 | D22: Integración (API) | E22: Patch me password exige la actual | G22: API levantada sobre PostgreSQL 16; Empresa A registrada, aprobada y autenticada | H22: PATCH /api/v1/auth/me | I22: Patch me password exige la actual. HTTP 401, 400 ; código de error PASSWORD_ACTUAL_REQUERIDA, PASSWORD_ACTUAL_INVALIDA, PASSWORD_DEBIL. | J22: 1 | K22: 6 | L22: tests/test_auth.py::test_patch_me_password_exige_la_actual | N22: Pendiente
A23: CP-AUT-22 | B23: Autenticación y cuentas | C23: RF-03 / RNF-03 | D23: Integración (API) | E23: Patch me password conserva la sesion indicada | F23: Enviar el refresh de la sesión en curso evita que se cierre. | G23: API levantada sobre PostgreSQL 16; Empresa A registrada, aprobada y autenticada | H23: PATCH /api/v1/auth/me · POST /api/v1/auth/refresh | I23: Patch me password conserva la sesion indicada. HTTP 200. | J23: 1 | K23: 3 | L23: tests/test_auth.py::test_patch_me_password_conserva_la_sesion_indicada | N23: Pendiente
A24: CP-AUT-23 | B24: Autenticación y cuentas | C24: RF-03 / RNF-03 | D24: Integración (API) | E24: Patch me password cierra las demas sesiones | G24: API levantada sobre PostgreSQL 16; Empresa A registrada, aprobada y autenticada | H24: POST /api/v1/auth/login · PATCH /api/v1/auth/me · POST /api/v1/auth/refresh | I24: Patch me password cierra las demas sesiones. HTTP 200, 401. | J24: 1 | K24: 4 | L24: tests/test_auth.py::test_patch_me_password_cierra_las_demas_sesiones | N24: Pendiente
A25: CP-AUT-24 | B25: Autenticación y cuentas | C25: RF-02 | D25: Integración (API) | E25: Company no puede usar endpoints de admin | G25: API levantada sobre PostgreSQL 16; Empresa A registrada, aprobada y autenticada | H25: GET /api/v1/admin/companies | I25: Company no puede usar endpoints de admin. HTTP 403 ; código de error SOLO_ADMIN. | J25: 1 | K25: 2 | L25: tests/test_auth.py::test_company_no_puede_usar_endpoints_de_admin | N25: Pendiente
A26: CP-AUT-25 | B26: Autenticación y cuentas | C26: RF-02 | D26: Integración (API) | E26: Admin necesita company id para datos de empresa | G26: API levantada sobre PostgreSQL 16; Usuario administrador de la plataforma | H26: GET /api/v1/contratos | I26: Admin necesita company id para datos de empresa. HTTP 400 ; código de error COMPANY_ID_REQUERIDO, COMPANY_ID_INVALIDO. | J26: 1 | K26: 4 | L26: tests/test_auth.py::test_admin_necesita_company_id_para_datos_de_empresa | N26: Pendiente
A27: CP-AUT-26 | B27: Autenticación y cuentas | C27: RF-02 | D27: Integración (API) | E27: Admin impersona con x company id | G27: API levantada sobre PostgreSQL 16; Usuario administrador de la plataforma; Empresa A registrada, aprobada y autenticada; Contrato de la empresa A en Los Pelambres | H27: GET /api/v1/contratos | I27: Admin impersona con x company id. HTTP 200. | J27: 1 | K27: 2 | L27: tests/test_auth.py::test_admin_impersona_con_x_company_id | N27: Pendiente
A28: CP-AUT-27 | B28: Autenticación y cuentas | C28: RF-02 | D28: Integración (API) | E28: Contract admin no muta datos de empresa | F28: `require_company` excluye al contract_admin de las mutaciones de empresa. | G28: API levantada sobre PostgreSQL 16; Empresa A registrada, aprobada y autenticada; Contrato de la empresa A en Los Pelambres | H28: GET /api/v1/auth/me · POST /api/v1/company/usuarios | I28: Contract admin no muta datos de empresa. HTTP 200, 403 ; código de error ROL_INSUFICIENTE. | J28: 1 | K28: 6 | L28: tests/test_auth.py::test_contract_admin_no_muta_datos_de_empresa | N28: Pendiente
A29: CP-AUT-28 | B29: Autenticación y cuentas | C29: RF-04 | D29: Integración (API) | E29: Invitar usuario valida el rol | G29: API levantada sobre PostgreSQL 16; Empresa A registrada, aprobada y autenticada; Contrato de la empresa A en Los Pelambres | H29: POST /api/v1/company/usuarios | I29: Invitar usuario valida el rol. HTTP 400 ; código de error CONTRATO_REQUERIDO, CONTRATO_NO_APLICA, ROL_INVALIDO. | J29: 1 | K29: 6 | L29: tests/test_auth.py::test_invitar_usuario_valida_el_rol | N29: Pendiente
A30: CP-CON-01 | B30: Contratos y requisitos | C30: RF-06 / RN-04 | D30: Integración (API) | E30: Alta instancia el checklist de empresa | G30: API levantada sobre PostgreSQL 16; Empresa A registrada, aprobada y autenticada; Faena Los Pelambres en el catálogo | H30: POST /api/v1/contratos · GET /api/v1/contratos/{id}/documentos?page_size=100 | I30: Alta instancia el checklist de empresa. HTTP 201. | J30: 1 | K30: 6 | L30: tests/test_contratos.py::test_alta_instancia_el_checklist_de_empresa | N30: Pendiente
A31: CP-CON-02 | B31: Contratos y requisitos | C31: RF-06 | D31: Integración (API) | E31: Listado valida el estado | G31: API levantada sobre PostgreSQL 16; Empresa A registrada, aprobada y autenticada; Contrato de la empresa A en Los Pelambres | H31: GET /api/v1/contratos?estado=inventado | I31: Listado valida el estado. HTTP 400 ; código de error ESTADO_INVALIDO. | J31: 1 | K31: 2 | L31: tests/test_contratos.py::test_listado_valida_el_estado | N31: Pendiente
A32: CP-CON-03 | B32: Contratos y requisitos | C32: RF-06 | D32: Integración (API) | E32: Ia review de otra empresa no se puede referenciar | G32: API levantada sobre PostgreSQL 16; Empresa A registrada, aprobada y autenticada; Faena Los Pelambres en el catálogo | H32: POST /api/v1/contratos | I32: Ia review de otra empresa no se puede referenciar. HTTP 404. | J32: 1 | K32: 1 | L32: tests/test_contratos.py::test_ia_review_de_otra_empresa_no_se_puede_referenciar | N32: Pendiente
A33: CP-CON-04 | B33: Contratos y requisitos | C33: RF-06 | D33: Integración (API) | E33: Borrar el contrato purga sujetos y archivos | G33: API levantada sobre PostgreSQL 16; Empresa A registrada, aprobada y autenticada; Contrato de la empresa A en Los Pelambres | H33: POST /api/v1/personal · GET /api/v1/contratos/{id}/documentos · DELETE /api/v1/contratos/{id} · DELETE /api/v1/contratos/{id}?confirm=true … | I33: Borrar el contrato purga sujetos y archivos. HTTP 400, 200, 404. | J33: 1 | K33: 5 | L33: tests/test_contratos.py::test_borrar_el_contrato_purga_sujetos_y_archivos | N33: Pendiente
A34: CP-CON-05 | B34: Contratos y requisitos | C34: RF-07 | D34: Integración (API) | E34: Contrato nuevo hereda las plataformas de la faena | G34: API levantada sobre PostgreSQL 16; Empresa A registrada, aprobada y autenticada; Contrato de la empresa A en Los Pelambres | H34: GET /api/v1/contratos/{id}/plataformas | I34: Contrato nuevo hereda las plataformas de la faena. HTTP 200. | J34: 1 | K34: 7 | L34: tests/test_contratos.py::test_contrato_nuevo_hereda_las_plataformas_de_la_faena | N34: Pendiente
A35: CP-CON-06 | B35: Contratos y requisitos | C35: RF-07 | D35: Integración (API) | E35: La primera manual materializa las heredadas | F35: El riesgo real: insertar la primera fila propia no debe borrar la herencia. | G35: API levantada sobre PostgreSQL 16; Empresa A registrada, aprobada y autenticada; Contrato de la empresa A en Los Pelambres | H35: POST /api/v1/contratos/{id}/plataformas · GET /api/v1/contratos/{id}/plataformas | I35: La primera manual materializa las heredadas. HTTP 201. | J35: 1 | K35: 9 | L35: tests/test_contratos.py::test_la_primera_manual_materializa_las_heredadas | N35: Pendiente
A36: CP-CON-07 | B36: Contratos y requisitos | C36: RF-07 | D36: Integración (API) | E36: Nombre duplicado de plataforma | F36: El choque se detecta contra la lista EFECTIVA, incluidas las heredadas. | G36: API levantada sobre PostgreSQL 16; Empresa A registrada, aprobada y autenticada; Contrato de la empresa A en Los Pelambres | H36: POST /api/v1/contratos/{id}/plataformas | I36: Nombre duplicado de plataforma. HTTP 409 ; código de error PLATAFORMA_DUPLICADA. | J36: 1 | K36: 2 | L36: tests/test_contratos.py::test_nombre_duplicado_de_plataforma | N36: Pendiente
A37: CP-CON-08 | B37: Contratos y requisitos | C37: RF-07 | D37: Integración (API) | E37: No se borra una plataforma heredada | F37: Una plataforma del mandante no desaparece: se pone en `sin_acceso`. | G37: API levantada sobre PostgreSQL 16; Empresa A registrada, aprobada y autenticada; Contrato de la empresa A en Los Pelambres | H37: GET /api/v1/contratos/{id}/plataformas · DELETE /api/v1/contratos/{id}/plataformas/{id}?confirm=true · POST /api/v1/contratos/{id}/plataformas · DELETE /api/v1/contratos/{id}/plataformas/{id} | I37: No se borra una plataforma heredada. HTTP 409 ; código de error PLATAFORMA_HEREDADA. | J37: 1 | K37: 4 | L37: tests/test_contratos.py::test_no_se_borra_una_plataforma_heredada | N37: Pendiente
A38: CP-CON-09 | B38: Contratos y requisitos | C38: RF-07 | D38: Integración (API) | E38: Se borra una plataforma manual con confirmacion | G38: API levantada sobre PostgreSQL 16; Empresa A registrada, aprobada y autenticada; Contrato de la empresa A en Los Pelambres | H38: POST /api/v1/contratos/{id}/plataformas · DELETE /api/v1/contratos/{id}/plataformas/{id} · DELETE /api/v1/contratos/{id}/plataformas/{id}?confirm=true · GET /api/v1/contratos/{id}/plataformas | I38: Se borra una plataforma manual con confirmacion. HTTP 400, 200 ; código de error REQUIERE_CONFIRMACION. | J38: 1 | K38: 7 | L38: tests/test_contratos.py::test_se_borra_una_plataforma_manual_con_confirmacion | N38: Pendiente
A39: CP-CON-10 | B39: Contratos y requisitos | C39: RF-06 | D39: Integración (API) | E39: Solicitar acceso fija las marcas que exige el check | F39: `estado='solicitada'` exige `solicitado_at` (CHECK ck_cplat_solicitud). | G39: API levantada sobre PostgreSQL 16; Empresa A registrada, aprobada y autenticada; Contrato de la empresa A en Los Pelambres | H39: GET /api/v1/contratos/{id}/plataformas · POST /api/v1/contratos/{id}/plataformas/ · PATCH /api/v1/contratos/{id}/plataformas/{id} · POST /api/v1/contratos/{id}/plataformas/{id} | I39: Solicitar acceso fija las marcas que exige el check. HTTP 200, 409 ; código de error PLATAFORMA_ACTIVA. | J39: 1 | K39: 9 | L39: tests/test_contratos.py::test_solicitar_acceso_fija_las_marcas_que_exige_el_check | N39: Pendiente
A40: CP-CON-11 | B40: Contratos y requisitos | C40: RF-07 | D40: Integración (API) | E40: Los vinculos incluyen plataformas y los fijos | G40: API levantada sobre PostgreSQL 16; Empresa A registrada, aprobada y autenticada; Contrato de la empresa A en Los Pelambres | H40: GET /api/v1/contratos/{id}/vinculos | I40: Los vinculos incluyen plataformas y los fijos. HTTP 200. | J40: 1 | K40: 4 | L40: tests/test_contratos.py::test_los_vinculos_incluyen_plataformas_y_los_fijos | N40: Pendiente
...
